Workbook
Name L_1.1: Recherche!$D$2:$D$6
Name L_1.1: Référentiel!$D$2:$D$6
Name L_1.2: Recherche!$D$7:$D$11
Name L_1.2: Référentiel!$D$7:$D$11
Name L_11: Recherche!$D$2:$D$6
Name L_11: Référentiel!$D$2:$D$6

Sheet Questionnaire
A1: Base TOGAF ACCM | E1: EVALUATION MATURITE ARCHITECTURE CAPABILITIES
D3: Note | E3: Questionnaire | F3: Commentaires
C4: 1. | D4: =AVERAGE(D6,D12,D18,D24,D30) -> 3.6 | E4: Architecture Governance Capability
E5: Assurer la cohérence des transformations et limiter les dérives
D6: =SUM(D7:D11) -> 2 | E6: 1Q1. Existe-t-il une gouvernance d’architecture clairement définie (comité d’architecture, processus de validation, etc.) ?
C7: FALSE | D7: =IF(C7=TRUE,1,"") | E7: Aucun comité d’architecture ni processus formel ; décisions au cas par cas.
C8: TRUE | D8: =IF(C8=TRUE,2,"") -> 2 | E8: Un comité est envisagé mais pas encore actif ; peu de formalisation.
C9: FALSE | D9: =IF(C9=TRUE,3,"") | E9: Comité existant avec rôles flous et gouvernance immature.
C10: FALSE | D10: =IF(C10=TRUE,4,"") | E10: Comité d’architecture bien défini, processus documenté et suivi.
C11: FALSE | D11: =IF(C11=TRUE,5,"") | E11: Gouvernance totalement intégrée et pilotée de façon stratégique.
D12: =SUM(D13:D17) -> 4 | E12: 1Q2. Les principes et standards d’architecture sont-ils documentés et appliqués de façon cohérente ?
C13: FALSE | D13: =IF(C13=TRUE,1,"") | E13: Aucun principe ni standard défini.
C14: FALSE | D14: =IF(C14=TRUE,2,"") | E14: Principes en cours de rédaction, non appliqués systématiquement.
C15: FALSE | D15: =IF(C15=TRUE,3,"") | E15: Principes définis mais appliqués de façon variable.
C16: TRUE | D16: =IF(C16=TRUE,4,"") -> 4 | E16: Principes formalisés, communiqués et appliqués régulièrement.
C17: FALSE | D17: =IF(C17=TRUE,5,"") | E17: Principes intégrés aux processus projets, suivis et améliorés.
D18: =SUM(D19:D23) -> 3 | E18: 1Q3. Les dérogations ou exceptions sont-elles formellement gérées et suivies ?
C19: FALSE | D19: =IF(C19=TRUE,1,"") | E19: Aucune gestion des dérogations.
C20: FALSE | D20: =IF(C20=TRUE,2,"") | E20: Gestion informelle des dérogations au cas par cas.
C21: TRUE | D21: =IF(C21=TRUE,3,"") -> 3 | E21: Processus partiellement défini, dérogations tracées mais analyse incomplète.
C22: FALSE | D22: =IF(C22=TRUE,4,"") | E22: Processus formalisé, dérogations documentées et analysées.
C23: FALSE | D23: =IF(C23=TRUE,5,"") | E23: Gestion des dérogations intégrée et optimisée, avec reporting.
D24: =SUM(D25:D29) -> 5 | E24: 1Q4. Les décisions d’architecture sont-elles prises de manière transparente et tracées ?
C25: FALSE | D25: =IF(C25=TRUE,1,"") | E25: Décisions prises de manière ad hoc et non documentées.
C26: FALSE | D26: =IF(C26=TRUE,2,"") | E26: Certaines décisions sont documentées mais la traçabilité est limitée.
C27: FALSE | D27: =IF(C27=TRUE,3,"") | E27: Décisions tracées mais manque de communication.
C28: FALSE | D28: =IF(C28=TRUE,4,"") | E28: Décisions documentées, tracées et communiquées.
C29: TRUE | D29: =IF(C29=TRUE,5,"") -> 5 | E29: Décisions tracées et disponibles via outil/référentiel.
D30: =SUM(D31:D35) -> 4 | E30: 1Q5. Les parties prenantes (métiers et IT) participent-elles aux décisions d’architecture ?
C31: FALSE | D31: =IF(C31=TRUE,1,"") | E31: Aucune implication des parties prenantes.
C32: FALSE | D32: =IF(C32=TRUE,2,"") | E32: Consultation ponctuelle des parties prenantes.
C33: FALSE | D33: =IF(C33=TRUE,3,"") | E33: Parties prenantes consultées mais peu impliquées.
C34: TRUE | D34: =IF(C34=TRUE,4,"") -> 4 | E34: Participation active des parties prenantes aux décisions importantes.
C35: FALSE | D35: =IF(C35=TRUE,5,"") | E35: Parties prenantes impliquées systématiquement et proactivement.
C36: 2. | D36: =AVERAGE(D38,D44,D50,D56,D62) -> 3 | E36: Architecture Practice Process Method Capability
E37: Standardiser les pratiques pour produire des résultats reproductibles et cohérents
D38: =SUM(D39:D43) -> 2 | E38: 2Q1. Une méthodologie d’architecture (TOGAF, Zachman ou autre) est-elle adoptée et adaptée au contexte ?
C39: FALSE | D39: =IF(C39=TRUE,1,"") | E39: Aucune méthodologie formelle d’architecture n’a été identifiée ou utilisée.
C40: TRUE | D40: =IF(C40=TRUE,2,"") -> 2 | E40: Une méthodologie est envisagée mais pas encore formalisée ; quelques architectes l’appliquent ponctuellement.
C41: FALSE | D41: =IF(C41=TRUE,3,"") | E41: Une méthodologie est définie mais son application varie d’un projet à l’autre, sans standardisation.
...

Sheet Synthèse Résultats
B1: Résultats :
B4: ARCHITECTURE CAPABILITIES | D4: =AVERAGE(D5,D7,D9,D11,D13,D15,D17,D19,D21) -> 2.7777778
A5: =Questionnaire!E4 -> Architecture Governance Capability | B5: {=_xlfn.TEXTSPLIT(A5," Capability")} -> Architecture Governance | D5: =Questionnaire!D4 -> 3.6
B6: Assurer la cohérence des transformations et limiter les dérives
A7: =Questionnaire!E36 -> Architecture Practice Process Method Capability | B7: {=_xlfn.TEXTSPLIT(A7," Capability")} -> Architecture Practice Process Method | D7: =Questionnaire!D36 -> 3
B8: Standardiser les pratiques pour produire des résultats reproductibles et cohérents
A9: =Questionnaire!E68 -> Business & IT Strategy Linkage Capability | B9: {=_xlfn.TEXTSPLIT(A9," Capability")} -> Business & IT Strategy Linkage | D9: =Questionnaire!D68 -> 1.8
B10: S’assurer que l’architecture soutient réellement les besoins métiers
A11: =Questionnaire!E100 -> Communication Capability | B11: {=_xlfn.TEXTSPLIT(A11," Capability")} -> Communication | D11: =Questionnaire!D100 -> 2.6
B12: Favoriser l’adhésion et la compréhension de l’architecture
A13: =Questionnaire!E132 -> Tools & Repository Capability | B13: {=_xlfn.TEXTSPLIT(A13," Capability")} -> Tools & Repository | D13: =Questionnaire!D132 -> 3
B14: Structurer et capitaliser les connaissances en architecture
A15: =Questionnaire!E164 -> People and Team Capability | B15: {=_xlfn.TEXTSPLIT(A15," Capability")} -> People and Team | D15: =Questionnaire!D164 -> 1.4
B16: Disposer des bonnes ressources pour porter l’architecture
A17: =Questionnaire!E196 -> Architecture Content & Deliverables Capability | B17: {=_xlfn.TEXTSPLIT(A17," Capability")} -> Architecture Content & Deliverables | D17: =Questionnaire!D196 -> 4
B18: Apporter de la valeur aux parties prenantes grâce à des livrables clairs et actionnables
A19: =Questionnaire!E228 -> Architecture Metrics Measurement Capability | B19: {=_xlfn.TEXTSPLIT(A19," Capability")} -> Architecture Metrics Measurement | D19: =Questionnaire!D228 -> 2.2
B20: Piloter la performance de l’architecture et démontrer sa valeur
A21: =Questionnaire!E260 -> Organisational Capability | B21: {=_xlfn.TEXTSPLIT(A21," Capability")} -> Organisational | D21: =Questionnaire!D260 -> 3.4
B22: La capacité de l’organisation à soutenir et institutionnaliser l’architecture d’entreprise dans sa gouvernance globale
B24: Les grandes entreprises se situent en général entre 3,5 et 4 points en moyenne de maturité

Sheet Urgent
C2: Axes à traiter en urgence (Notes inférieures à 2) | D2: Note
C3: =Questionnaire!E4 -> Architecture Governance Capability | D3: =Questionnaire!D4 -> 3.6
C4: =Questionnaire!E5 -> Assurer la cohérence des transformations et limiter les dérives | D4: =Questionnaire!D5 -> 0
B5: =VLOOKUP(C5,Recherche!$B$2:$E$226,4) -> 1. Architecture Governance Capability | C5: =Questionnaire!E6 -> 1Q1. Existe-t-il une gouvernance d’architecture clairement définie (comité d’architecture, processus de validation, etc.) ? | D5: =Questionnaire!D6 -> 2
C6: =Questionnaire!E7 -> Aucun comité d’architecture ni processus formel ; décisions au cas par cas. | D6: =Questionnaire!D7
C7: =Questionnaire!E8 -> Un comité est envisagé mais pas encore actif ; peu de formalisation. | D7: =Questionnaire!D8 -> 2
C8: =Questionnaire!E9 -> Comité existant avec rôles flous et gouvernance immature. | D8: =Questionnaire!D9
C9: =Questionnaire!E10 -> Comité d’architecture bien défini, processus documenté et suivi. | D9: =Questionnaire!D10
C10: =Questionnaire!E11 -> Gouvernance totalement intégrée et pilotée de façon stratégique. | D10: =Questionnaire!D11
C11: =Questionnaire!E12 -> 1Q2. Les principes et standards d’architecture sont-ils documentés et appliqués de façon cohérente ? | D11: =Questionnaire!D12 -> 4
C12: =Questionnaire!E13 -> Aucun principe ni standard défini. | D12: =Questionnaire!D13
C13: =Questionnaire!E14 -> Principes en cours de rédaction, non appliqués systématiquement. | D13: =Questionnaire!D14
C14: =Questionnaire!E15 -> Principes définis mais appliqués de façon variable. | D14: =Questionnaire!D15
C15: =Questionnaire!E16 -> Principes formalisés, communiqués et appliqués régulièrement. | D15: =Questionnaire!D16 -> 4
C16: =Questionnaire!E17 -> Principes intégrés aux processus projets, suivis et améliorés. | D16: =Questionnaire!D17
C17: =Questionnaire!E18 -> 1Q3. Les dérogations ou exceptions sont-elles formellement gérées et suivies ? | D17: =Questionnaire!D18 -> 3
... C36: =Questionnaire!E37 -> Standardiser les pratiques pour produire des résultats reproductibles et cohérents | D36: =Questionnaire!D37 -> 0
B37: =VLOOKUP(C37,Recherche!$B$2:$E$226,4) -> 2. Architecture Practice Process Method Capability | C37: =Questionnaire!E38 -> 2Q1. Une méthodologie d’architecture (TOGAF, Zachman ou autre) est-elle adoptée et adaptée au contexte ? | D37: =Questionnaire!D38 -> 2
C38: =Questionnaire!E39 -> Aucune méthodologie formelle d’architecture n’a été identifiée ou utilisée. | D38: =Questionnaire!D39
C39: =Questionnaire!E40 -> Une méthodologie est envisagée mais pas encore formalisée ; quelques architectes l’appliquent ponctuellement. | D39: =Questionnaire!D40 -> 2
C40: =Questionnaire!E41 -> Une méthodologie est définie mais son application varie d’un projet à l’autre, sans standardisation. | D40: =Questionnaire!D41
C41: =Questionnaire!E42 -> Une méthodologie est adoptée, adaptée au contexte, et utilisée régulièrement sur la plupart des projets. | D41: =Questionnaire!D42
C42: =Questionnaire!E43 -> La méthodologie est totalement intégrée, adaptée en continu, et soutenue par des formations et des guides pratiques. | D42: =Questionnaire!D43
C43: =Questionnaire!E44 -> 2Q2. Les étapes et les livrables du processus d’architecture sont-ils clairement définis ? | D43: =Questionnaire!D44 -> 3
C44: =Questionnaire!E45 -> Aucun processus ni livrable défini. Chaque architecte fait selon ses habitudes. | D44: =Questionnaire!D45
C45: =Questionnaire!E46 -> Quelques livrables sont définis mais pas alignés avec un processus structuré. | D45: =Questionnaire!D46
C46: =Questionnaire!E47 -> Les étapes et les livrables sont définis mais pas systématiquement appliqués. | D46: =Questionnaire!D47 -> 3
C47: =Questionnaire!E48 -> Les étapes et les livrables sont définis, normalisés et connus des équipes. | D47: =Questionnaire!D48
C48: =Questionnaire!E49 -> Les étapes et les livrables sont standardisés, adaptés selon le contexte projet et audités régulièrement. | D48: =Questionnaire!D49
C49: =Questionnaire!E50 -> 2Q3. Les architectes appliquent-ils systématiquement la méthodologie définie ? | D49: =Questionnaire!D50 -> 4
... C68: =Questionnaire!E69 -> S’assurer que l’architecture soutient réellement les besoins métiers | D68: =Questionnaire!D69 -> 0
B69: =VLOOKUP(C69,Recherche!$B$2:$E$226,4) -> 3. Business & IT Strategy Linkage Capability | C69: =Questionnaire!E70 -> 3Q1. L’architecture est-elle alignée avec la stratégie métier de l’organisation ? | D69: =Questionnaire!D70 -> 2
C70: =Questionnaire!E71 -> Aucun alignement entre l’architecture et la stratégie métier. | D70: =Questionnaire!D71
C71: =Questionnaire!E72 -> Alignement en réflexion mais pas encore formalisé. | D71: =Questionnaire!D72 -> 2
C72: =Questionnaire!E73 -> Alignement partiel mais manque de cohérence. | D72: =Questionnaire!D73
C73: =Questionnaire!E74 -> Alignement opérationnel avec la stratégie métier. | D73: =Questionnaire!D74
C74: =Questionnaire!E75 -> Alignement stratégique parfaitement intégré aux processus d’architecture. | D74: =Questionnaire!D75
C75: =Questionnaire!E76 -> 3Q2. Les besoins métiers sont-ils systématiquement intégrés dans les décisions d’architecture ? | D75: =Questionnaire!D76 -> 2
C76: =Questionnaire!E77 -> Les besoins métiers ne sont pas pris en compte. | D76: =Questionnaire!D77
C77: =Questionnaire!E78 -> Intégration ponctuelle des besoins métiers. | D77: =Questionnaire!D78 -> 2
...

Sheet A améliorer
C2: Axes à traiter à court terme (Notes <3 et >=2) | D2: Note
C3: =Questionnaire!E4 -> Architecture Governance Capability | D3: =Questionnaire!D4 -> 3.6
C4: =Questionnaire!E5 -> Assurer la cohérence des transformations et limiter les dérives | D4: =Questionnaire!D5 -> 0
B5: =VLOOKUP(C5,Recherche!$B$2:$E$226,4) -> 1. Architecture Governance Capability | C5: =Questionnaire!E6 -> 1Q1. Existe-t-il une gouvernance d’architecture clairement définie (comité d’architecture, processus de validation, etc.) ? | D5: =Questionnaire!D6 -> 2
C6: =Questionnaire!E7 -> Aucun comité d’architecture ni processus formel ; décisions au cas par cas. | D6: =Questionnaire!D7
C7: =Questionnaire!E8 -> Un comité est envisagé mais pas encore actif ; peu de formalisation. | D7: =Questionnaire!D8 -> 2
C8: =Questionnaire!E9 -> Comité existant avec rôles flous et gouvernance immature. | D8: =Questionnaire!D9
C9: =Questionnaire!E10 -> Comité d’architecture bien défini, processus documenté et suivi. | D9: =Questionnaire!D10
C10: =Questionnaire!E11 -> Gouvernance totalement intégrée et pilotée de façon stratégique. | D10: =Questionnaire!D11
C11: =Questionnaire!E12 -> 1Q2. Les principes et standards d’architecture sont-ils documentés et appliqués de façon cohérente ? | D11: =Questionnaire!D12 -> 4
C12: =Questionnaire!E13 -> Aucun principe ni standard défini. | D12: =Questionnaire!D13
C13: =Questionnaire!E14 -> Principes en cours de rédaction, non appliqués systématiquement. | D13: =Questionnaire!D14
C14: =Questionnaire!E15 -> Principes définis mais appliqués de façon variable. | D14: =Questionnaire!D15
C15: =Questionnaire!E16 -> Principes formalisés, communiqués et appliqués régulièrement. | D15: =Questionnaire!D16 -> 4
C16: =Questionnaire!E17 -> Principes intégrés aux processus projets, suivis et améliorés. | D16: =Questionnaire!D17
C17: =Questionnaire!E18 -> 1Q3. Les dérogations ou exceptions sont-elles formellement gérées et suivies ? | D17: =Questionnaire!D18 -> 3
... C36: =Questionnaire!E37 -> Standardiser les pratiques pour produire des résultats reproductibles et cohérents | D36: =Questionnaire!D37 -> 0
B37: =VLOOKUP(C37,Recherche!$B$2:$E$226,4) -> 2. Architecture Practice Process Method Capability | C37: =Questionnaire!E38 -> 2Q1. Une méthodologie d’architecture (TOGAF, Zachman ou autre) est-elle adoptée et adaptée au contexte ? | D37: =Questionnaire!D38 -> 2
C38: =Questionnaire!E39 -> Aucune méthodologie formelle d’architecture n’a été identifiée ou utilisée. | D38: =Questionnaire!D39
C39: =Questionnaire!E40 -> Une méthodologie est envisagée mais pas encore formalisée ; quelques architectes l’appliquent ponctuellement. | D39: =Questionnaire!D40 -> 2
C40: =Questionnaire!E41 -> Une méthodologie est définie mais son application varie d’un projet à l’autre, sans standardisation. | D40: =Questionnaire!D41
C41: =Questionnaire!E42 -> Une méthodologie est adoptée, adaptée au contexte, et utilisée régulièrement sur la plupart des projets. | D41: =Questionnaire!D42
C42: =Questionnaire!E43 -> La méthodologie est totalement intégrée, adaptée en continu, et soutenue par des formations et des guides pratiques. | D42: =Questionnaire!D43
C43: =Questionnaire!E44 -> 2Q2. Les étapes et les livrables du processus d’architecture sont-ils clairement définis ? | D43: =Questionnaire!D44 -> 3
C44: =Questionnaire!E45 -> Aucun processus ni livrable défini. Chaque architecte fait selon ses habitudes. | D44: =Questionnaire!D45
C45: =Questionnaire!E46 -> Quelques livrables sont définis mais pas alignés avec un processus structuré. | D45: =Questionnaire!D46
C46: =Questionnaire!E47 -> Les étapes et les livrables sont définis mais pas systématiquement appliqués. | D46: =Questionnaire!D47 -> 3
C47: =Questionnaire!E48 -> Les étapes et les livrables sont définis, normalisés et connus des équipes. | D47: =Questionnaire!D48
C48: =Questionnaire!E49 -> Les étapes et les livrables sont standardisés, adaptés selon le contexte projet et audités régulièrement. | D48: =Questionnaire!D49
C49: =Questionnaire!E50 -> 2Q3. Les architectes appliquent-ils systématiquement la méthodologie définie ? | D49: =Questionnaire!D50 -> 4
... C68: =Questionnaire!E69 -> S’assurer que l’architecture soutient réellement les besoins métiers | D68: =Questionnaire!D69 -> 0
B69: =VLOOKUP(C69,Recherche!$B$2:$E$226,4) -> 3. Business & IT Strategy Linkage Capability | C69: =Questionnaire!E70 -> 3Q1. L’architecture est-elle alignée avec la stratégie métier de l’organisation ? | D69: =Questionnaire!D70 -> 2
C70: =Questionnaire!E71 -> Aucun alignement entre l’architecture et la stratégie métier. | D70: =Questionnaire!D71
C71: =Questionnaire!E72 -> Alignement en réflexion mais pas encore formalisé. | D71: =Questionnaire!D72 -> 2
C72: =Questionnaire!E73 -> Alignement partiel mais manque de cohérence. | D72: =Questionnaire!D73
C73: =Questionnaire!E74 -> Alignement opérationnel avec la stratégie métier. | D73: =Questionnaire!D74
C74: =Questionnaire!E75 -> Alignement stratégique parfaitement intégré aux processus d’architecture. | D74: =Questionnaire!D75
C75: =Questionnaire!E76 -> 3Q2. Les besoins métiers sont-ils systématiquement intégrés dans les décisions d’architecture ? | D75: =Questionnaire!D76 -> 2
C76: =Questionnaire!E77 -> Les besoins métiers ne sont pas pris en compte. | D76: =Questionnaire!D77
C77: =Questionnaire!E78 -> Intégration ponctuelle des besoins métiers. | D77: =Questionnaire!D78 -> 2
...

Sheet Maintenir et renforcer
C2: Axes à renforcer (Notes <4 et >=3) | D2: Note
C3: =Questionnaire!E4 -> Architecture Governance Capability | D3: =Questionnaire!D4 -> 3.6
C4: =Questionnaire!E5 -> Assurer la cohérence des transformations et limiter les dérives | D4: =Questionnaire!D5 -> 0
B5: =VLOOKUP(C5,Recherche!$B$2:$E$226,4) -> 1. Architecture Governance Capability | C5: =Questionnaire!E6 -> 1Q1. Existe-t-il une gouvernance d’architecture clairement définie (comité d’architecture, processus de validation, etc.) ? | D5: =Questionnaire!D6 -> 2
C6: =Questionnaire!E7 -> Aucun comité d’architecture ni processus formel ; décisions au cas par cas. | D6: =Questionnaire!D7
C7: =Questionnaire!E8 -> Un comité est envisagé mais pas encore actif ; peu de formalisation. | D7: =Questionnaire!D8 -> 2
C8: =Questionnaire!E9 -> Comité existant avec rôles flous et gouvernance immature. | D8: =Questionnaire!D9
C9: =Questionnaire!E10 -> Comité d’architecture bien défini, processus documenté et suivi. | D9: =Questionnaire!D10
C10: =Questionnaire!E11 -> Gouvernance totalement intégrée et pilotée de façon stratégique. | D10: =Questionnaire!D11
C11: =Questionnaire!E12 -> 1Q2. Les principes et standards d’architecture sont-ils documentés et appliqués de façon cohérente ? | D11: =Questionnaire!D12 -> 4
C12: =Questionnaire!E13 -> Aucun principe ni standard défini. | D12: =Questionnaire!D13
C13: =Questionnaire!E14 -> Principes en cours de rédaction, non appliqués systématiquement. | D13: =Questionnaire!D14
C14: =Questionnaire!E15 -> Principes définis mais appliqués de façon variable. | D14: =Questionnaire!D15
C15: =Questionnaire!E16 -> Principes formalisés, communiqués et appliqués régulièrement. | D15: =Questionnaire!D16 -> 4
C16: =Questionnaire!E17 -> Principes intégrés aux processus projets, suivis et améliorés. | D16: =Questionnaire!D17
C17: =Questionnaire!E18 -> 1Q3. Les dérogations ou exceptions sont-elles formellement gérées et suivies ? | D17: =Questionnaire!D18 -> 3
... C36: =Questionnaire!E37 -> Standardiser les pratiques pour produire des résultats reproductibles et cohérents | D36: =Questionnaire!D37 -> 0
B37: =VLOOKUP(C37,Recherche!$B$2:$E$226,4) -> 2. Architecture Practice Process Method Capability | C37: =Questionnaire!E38 -> 2Q1. Une méthodologie d’architecture (TOGAF, Zachman ou autre) est-elle adoptée et adaptée au contexte ? | D37: =Questionnaire!D38 -> 2
C38: =Questionnaire!E39 -> Aucune méthodologie formelle d’architecture n’a été identifiée ou utilisée. | D38: =Questionnaire!D39
C39: =Questionnaire!E40 -> Une méthodologie est envisagée mais pas encore formalisée ; quelques architectes l’appliquent ponctuellement. | D39: =Questionnaire!D40 -> 2
C40: =Questionnaire!E41 -> Une méthodologie est définie mais son application varie d’un projet à l’autre, sans standardisation. | D40: =Questionnaire!D41
C41: =Questionnaire!E42 -> Une méthodologie est adoptée, adaptée au contexte, et utilisée régulièrement sur la plupart des projets. | D41: =Questionnaire!D42
C42: =Questionnaire!E43 -> La méthodologie est totalement intégrée, adaptée en continu, et soutenue par des formations et des guides pratiques. | D42: =Questionnaire!D43
C43: =Questionnaire!E44 -> 2Q2. Les étapes et les livrables du processus d’architecture sont-ils clairement définis ? | D43: =Questionnaire!D44 -> 3
C44: =Questionnaire!E45 -> Aucun processus ni livrable défini. Chaque architecte fait selon ses habitudes. | D44: =Questionnaire!D45
C45: =Questionnaire!E46 -> Quelques livrables sont définis mais pas alignés avec un processus structuré. | D45: =Questionnaire!D46
C46: =Questionnaire!E47 -> Les étapes et les livrables sont définis mais pas systématiquement appliqués. | D46: =Questionnaire!D47 -> 3
C47: =Questionnaire!E48 -> Les étapes et les livrables sont définis, normalisés et connus des équipes. | D47: =Questionnaire!D48
C48: =Questionnaire!E49 -> Les étapes et les livrables sont standardisés, adaptés selon le contexte projet et audités régulièrement. | D48: =Questionnaire!D49
C49: =Questionnaire!E50 -> 2Q3. Les architectes appliquent-ils systématiquement la méthodologie définie ? | D49: =Questionnaire!D50 -> 4
... C68: =Questionnaire!E69 -> S’assurer que l’architecture soutient réellement les besoins métiers | D68: =Questionnaire!D69 -> 0
B69: =VLOOKUP(C69,Recherche!$B$2:$E$226,4) -> 3. Business & IT Strategy Linkage Capability | C69: =Questionnaire!E70 -> 3Q1. L’architecture est-elle alignée avec la stratégie métier de l’organisation ? | D69: =Questionnaire!D70 -> 2
C70: =Questionnaire!E71 -> Aucun alignement entre l’architecture et la stratégie métier. | D70: =Questionnaire!D71
C71: =Questionnaire!E72 -> Alignement en réflexion mais pas encore formalisé. | D71: =Questionnaire!D72 -> 2
C72: =Questionnaire!E73 -> Alignement partiel mais manque de cohérence. | D72: =Questionnaire!D73
C73: =Questionnaire!E74 -> Alignement opérationnel avec la stratégie métier. | D73: =Questionnaire!D74
C74: =Questionnaire!E75 -> Alignement stratégique parfaitement intégré aux processus d’architecture. | D74: =Questionnaire!D75
C75: =Questionnaire!E76 -> 3Q2. Les besoins métiers sont-ils systématiquement intégrés dans les décisions d’architecture ? | D75: =Questionnaire!D76 -> 2
C76: =Questionnaire!E77 -> Les besoins métiers ne sont pas pris en compte. | D76: =Questionnaire!D77
C77: =Questionnaire!E78 -> Intégration ponctuelle des besoins métiers. | D77: =Questionnaire!D78 -> 2
...

Sheet Référentiel
A1: Capacité | B1: Question | C1: Score | D1: Réponse illustrative | E1: Q Forms
A2: 1. Architecture Governance Capability | B2: 1Q1. Existe-t-il une gouvernance d’architecture clairement définie (comité d’architecture, processus de validation, etc.) ? | C2: 1 | D2: Aucun comité d’architecture ni processus formel ; décisions au cas par cas. | E2: =C2&"-"&D2 -> 1-Aucun comité d’architecture ni processus formel ; décisions au cas par cas.
A3: 1. Architecture Governance Capability | B3: 1Q1. Existe-t-il une gouvernance d’architecture clairement définie (comité d’architecture, processus de validation, etc.) ? | C3: 2 | D3: Un comité est envisagé mais pas encore actif ; peu de formalisation. | E3: =C3&"-"&D3 -> 2-Un comité est envisagé mais pas encore actif ; peu de formalisation.
A4: 1. Architecture Governance Capability | B4: 1Q1. Existe-t-il une gouvernance d’architecture clairement définie (comité d’architecture, processus de validation, etc.) ? | C4: 3 | D4: Comité existant avec rôles flous et gouvernance immature. | E4: =C4&"-"&D4 -> 3-Comité existant avec rôles flous et gouvernance immature.
A5: 1. Architecture Governance Capability | B5: 1Q1. Existe-t-il une gouvernance d’architecture clairement définie (comité d’architecture, processus de validation, etc.) ? | C5: 4 | D5: Comité d’architecture bien défini, processus documenté et suivi. | E5: =C5&"-"&D5 -> 4-Comité d’architecture bien défini, processus documenté et suivi.
A6: 1. Architecture Governance Capability | B6: 1Q1. Existe-t-il une gouvernance d’architecture clairement définie (comité d’architecture, processus de validation, etc.) ? | C6: 5 | D6: Gouvernance totalement intégrée et pilotée de façon stratégique. | E6: =C6&"-"&D6 -> 5-Gouvernance totalement intégrée et pilotée de façon stratégique.
A7: 1. Architecture Governance Capability | B7: 1Q2. Les principes et standards d’architecture sont-ils documentés et appliqués de façon cohérente ? | C7: 1 | D7: Aucun principe ni standard défini. | E7: =C7&"-"&D7 -> 1-Aucun principe ni standard défini.
A8: 1. Architecture Governance Capability | B8: 1Q2. Les principes et standards d’architecture sont-ils documentés et appliqués de façon cohérente ? | C8: 2 | D8: Principes en cours de rédaction, non appliqués systématiquement. | E8: =C8&"-"&D8 -> 2-Principes en cours de rédaction, non appliqués systématiquement.
A9: 1. Architecture Governance Capability | B9: 1Q2. Les principes et standards d’architecture sont-ils documentés et appliqués de façon cohérente ? | C9: 3 | D9: Principes définis mais appliqués de façon variable. | E9: =C9&"-"&D9 -> 3-Principes définis mais appliqués de façon variable.
A10: 1. Architecture Governance Capability | B10: 1Q2. Les principes et standards d’architecture sont-ils documentés et appliqués de façon cohérente ? | C10: 4 | D10: Principes formalisés, communiqués et appliqués régulièrement. | E10: =C10&"-"&D10 -> 4-Principes formalisés, communiqués et appliqués régulièrement.
A11: 1. Architecture Governance Capability | B11: 1Q2. Les principes et standards d’architecture sont-ils documentés et appliqués de façon cohérente ? | C11: 5 | D11: Principes intégrés aux processus projets, suivis et améliorés. | E11: =C11&"-"&D11 -> 5-Principes intégrés aux processus projets, suivis et améliorés.
A12: 1. Architecture Governance Capability | B12: 1Q3. Les dérogations ou exceptions sont-elles formellement gérées et suivies ? | C12: 1 | D12: Aucune gestion des dérogations. | E12: =C12&"-"&D12 -> 1-Aucune gestion des dérogations.
A13: 1. Architecture Governance Capability | B13: 1Q3. Les dérogations ou exceptions sont-elles formellement gérées et suivies ? | C13: 2 | D13: Gestion informelle des dérogations au cas par cas. | E13: =C13&"-"&D13 -> 2-Gestion informelle des dérogations au cas par cas.
... A226: 9. Organisational Capability | B226: 9Q5. Les changements organisationnels prennent-ils systématiquement en compte les impacts sur l’architecture ? | C226: 5 | D226: Changements organisationnels systématiquement synchronisés avec l’architecture. | E226: =C226&"-"&D226 -> 5-Changements organisationnels systématiquement synchronisés avec l’architecture.

Sheet Recherche
B1: Question | C1: Score | D1: Réponse illustrative | E1: Capacité
B2: 1Q1. Existe-t-il une gouvernance d’architecture clairement définie (comité d’architecture, processus de validation, etc.) ? | C2: 1 | D2: Aucun comité d’architecture ni processus formel ; décisions au cas par cas. | E2: 1. Architecture Governance Capability
B3: 1Q1. Existe-t-il une gouvernance d’architecture clairement définie (comité d’architecture, processus de validation, etc.) ? | C3: 2 | D3: Un comité est envisagé mais pas encore actif ; peu de formalisation. | E3: 1. Architecture Governance Capability
B4: 1Q1. Existe-t-il une gouvernance d’architecture clairement définie (comité d’architecture, processus de validation, etc.) ? | C4: 3 | D4: Comité existant avec rôles flous et gouvernance immature. | E4: 1. Architecture Governance Capability
B5: 1Q1. Existe-t-il une gouvernance d’architecture clairement définie (comité d’architecture, processus de validation, etc.) ? | C5: 4 | D5: Comité d’architecture bien défini, processus documenté et suivi. | E5: 1. Architecture Governance Capability
B6: 1Q1. Existe-t-il une gouvernance d’architecture clairement définie (comité d’architecture, processus de validation, etc.) ? | C6: 5 | D6: Gouvernance totalement intégrée et pilotée de façon stratégique. | E6: 1. Architecture Governance Capability
B7: 1Q2. Les principes et standards d’architecture sont-ils documentés et appliqués de façon cohérente ? | C7: 1 | D7: Aucun principe ni standard défini. | E7: 1. Architecture Governance Capability
B8: 1Q2. Les principes et standards d’architecture sont-ils documentés et appliqués de façon cohérente ? | C8: 2 | D8: Principes en cours de rédaction, non appliqués systématiquement. | E8: 1. Architecture Governance Capability
B9: 1Q2. Les principes et standards d’architecture sont-ils documentés et appliqués de façon cohérente ? | C9: 3 | D9: Principes définis mais appliqués de façon variable. | E9: 1. Architecture Governance Capability
B10: 1Q2. Les principes et standards d’architecture sont-ils documentés et appliqués de façon cohérente ? | C10: 4 | D10: Principes formalisés, communiqués et appliqués régulièrement. | E10: 1. Architecture Governance Capability
B11: 1Q2. Les principes et standards d’architecture sont-ils documentés et appliqués de façon cohérente ? | C11: 5 | D11: Principes intégrés aux processus projets, suivis et améliorés. | E11: 1. Architecture Governance Capability
B12: 1Q3. Les dérogations ou exceptions sont-elles formellement gérées et suivies ? | C12: 1 | D12: Aucune gestion des dérogations. | E12: 1. Architecture Governance Capability
B13: 1Q3. Les dérogations ou exceptions sont-elles formellement gérées et suivies ? | C13: 2 | D13: Gestion informelle des dérogations au cas par cas. | E13: 1. Architecture Governance Capability
... B226: 9Q5. Les changements organisationnels prennent-ils systématiquement en compte les impacts sur l’architecture ? | C226: 5 | D226: Changements organisationnels systématiquement synchronisés avec l’architecture. | E226: 9. Organisational Capability
